<?xml version="1.0"?>
<robot name="my_custom_bot">

    <material name="white"><color rgba="1 1 1 1"/></material>
    <material name="black"><color rgba="0 0 0 1"/></material>
    <material name="blue"><color rgba="0 0 1 1"/></material>
    <material name="red"><color rgba="1 0 0 1"/></material>

    <link name="base_footprint"/>

    <joint name="base_joint" type="fixed">
        <parent link="base_footprint"/>
        <child link="base_link"/>
        <origin xyz="0 0 0.05"/> </joint>

    <link name="base_link">
        <visual>
            <origin xyz="0 0 0" rpy="0 0 0"/>
            <geometry><box size="0.4 0.3 0.1"/></geometry> <material name="white"/>
        </visual>
        <collision>
            <geometry><box size="0.4 0.3 0.1"/></geometry>
        </collision>
        <inertial>
            <mass value="5.0"/> <inertia ixx="0.04" ixy="0" ixz="0" iyy="0.07" iyz="0" izz="0.1"/>
        </inertial>
    </link>

    <joint name="left_wheel_joint" type="continuous"> <parent link="base_link"/>
        <child link="left_wheel"/>
        <origin xyz="0 0.175 0" rpy="-1.5707 0 0"/> <axis xyz="0 0 1"/> </joint>

    <link name="left_wheel">
        <visual>
            <geometry><cylinder radius="0.05" length="0.04"/></geometry> <material name="black"/>
        </visual>
        <collision>
            <geometry><cylinder radius="0.05" length="0.04"/></geometry>
        </collision>
        <inertial>
            <mass value="0.5"/>
            <inertia ixx="0.0004" ixy="0" ixz="0" iyy="0.0004" iyz="0" izz="0.0006"/>
        </inertial>
    </link>

    <joint name="right_wheel_joint" type="continuous">
        <parent link="base_link"/>
        <child link="right_wheel"/>
        <origin xyz="0 -0.175 0" rpy="1.5707 0 0"/> <axis xyz="0 0 -1"/>
    </joint>

    <link name="right_wheel">
        <visual>
            <geometry><cylinder radius="0.05" length="0.04"/></geometry>
            <material name="black"/>
        </visual>
        <collision>
            <geometry><cylinder radius="0.05" length="0.04"/></geometry>
        </collision>
        <inertial>
            <mass value="0.5"/>
            <inertia ixx="0.0004" ixy="0" ixz="0" iyy="0.0004" iyz="0" izz="0.0006"/>
        </inertial>
    </link>

    <joint name="caster_joint" type="fixed">
        <parent link="base_link"/>
        <child link="caster_wheel"/>
        <origin xyz="-0.15 0 -0.025" rpy="0 0 0"/> </joint>

    <link name="caster_wheel">
        <visual>
            <geometry><sphere radius="0.025"/></geometry> <material name="black"/>
        </visual>
        <collision>
            <geometry><sphere radius="0.025"/></geometry>
        </collision>
        <inertial>
            <mass value="0.2"/>
            <inertia ixx="0.0001" ixy="0" ixz="0" iyy="0.0001" iyz="0" izz="0.0001"/>
        </inertial>
    </link>

    <joint name="lidar_joint" type="fixed">
        <parent link="base_link"/>
        <child link="lidar_link"/>
        <origin xyz="0.15 0 0.075" rpy="0 0 0"/> </joint>

    <link name="lidar_link">
        <visual>
            <geometry><cylinder radius="0.04" length="0.05"/></geometry> <material name="blue"/>
        </visual>
        <collision>
            <geometry><cylinder radius="0.04" length="0.05"/></geometry>
        </collision>
        <inertial>
            <mass value="0.1"/>
            <inertia ixx="0.0001" ixy="0" ixz="0" iyy="0.0001" iyz="0" izz="0.0001"/>
        </inertial>
    </link>


<gazebo reference="caster_wheel">
        <mu1>0.0</mu1>
        <mu2>0.0</mu2>
    </gazebo>

    <gazebo>
        <plugin filename="gz-sim-diff-drive-system" name="gz::sim::systems::DiffDrive">
            <left_joint>left_wheel_joint</left_joint>
            <right_joint>right_wheel_joint</right_joint>
            <wheel_separation>0.35</wheel_separation> <wheel_radius>0.05</wheel_radius> <odom_publish_frequency>50</odom_publish_frequency>
            <topic>cmd_vel</topic>
            <odom_topic>odom</odom_topic>
            <frame_id>odom</frame_id>
            <child_frame_id>base_footprint</child_frame_id>
        </plugin>

        <plugin filename="gz-sim-sensors-system" name="gz::sim::systems::Sensors">
            <render_engine>ogre2</render_engine>
        </plugin>
    </gazebo>

    <gazebo reference="lidar_link">
        <sensor name="lidar" type="gpu_lidar">
            <pose>0 0 0 0 0 0</pose>
            <topic>scan</topic>
            <update_rate>10</update_rate>
            <ray>
                <scan>
                    <horizontal>
                        <samples>180</samples> 
                        <resolution>1</resolution>
                        <min_angle>-1.57079</min_angle> 
                        <max_angle>1.57079</max_angle>  
                    </horizontal>
                </scan>
                <range>
                    <min>0.08</min> <max>12.0</max> 
                    <resolution>0.01</resolution>
                </range>
            </ray>
            <always_on>1</always_on>
            <visualize>true</visualize> </sensor>
    </gazebo>


</robot>
